[2025-10-06T18:24:26.526+0000] {taskinstance.py:1083} INFO - Dependencies all met for <TaskInstance: Airflow_Lab1.load_model_task manual__2025-10-06T18:24:18.874182+00:00 [queued]>
[2025-10-06T18:24:26.529+0000] {taskinstance.py:1083} INFO - Dependencies all met for <TaskInstance: Airflow_Lab1.load_model_task manual__2025-10-06T18:24:18.874182+00:00 [queued]>
[2025-10-06T18:24:26.529+0000] {taskinstance.py:1279} INFO - 
--------------------------------------------------------------------------------
[2025-10-06T18:24:26.529+0000] {taskinstance.py:1280} INFO - Starting attempt 1 of 1
[2025-10-06T18:24:26.529+0000] {taskinstance.py:1281} INFO - 
--------------------------------------------------------------------------------
[2025-10-06T18:24:26.534+0000] {taskinstance.py:1300} INFO - Executing <Task(PythonOperator): load_model_task> on 2025-10-06 18:24:18.874182+00:00
[2025-10-06T18:24:26.536+0000] {standard_task_runner.py:55} INFO - Started process 8553 to run task
[2025-10-06T18:24:26.538+0000] {standard_task_runner.py:82} INFO - Running: ['***', 'tasks', 'run', 'Airflow_Lab1', 'load_model_task', 'manual__2025-10-06T18:24:18.874182+00:00', '--job-id', '28', '--raw', '--subdir', 'DAGS_FOLDER/***.py', '--cfg-path', '/tmp/tmplhij_q8q']
[2025-10-06T18:24:26.538+0000] {standard_task_runner.py:83} INFO - Job 28: Subtask load_model_task
[2025-10-06T18:24:26.561+0000] {task_command.py:388} INFO - Running <TaskInstance: Airflow_Lab1.load_model_task manual__2025-10-06T18:24:18.874182+00:00 [running]> on host 7b2411da06e7
[2025-10-06T18:24:26.587+0000] {taskinstance.py:1509} INFO - Exporting the following env vars:
AIRFLOW_CTX_DAG_OWNER=your_name
AIRFLOW_CTX_DAG_ID=Airflow_Lab1
AIRFLOW_CTX_TASK_ID=load_model_task
AIRFLOW_CTX_EXECUTION_DATE=2025-10-06T18:24:18.874182+00:00
AIRFLOW_CTX_TRY_NUMBER=1
AIRFLOW_CTX_DAG_RUN_ID=manual__2025-10-06T18:24:18.874182+00:00
[2025-10-06T18:24:26.588+0000] {logging_mixin.py:137} INFO - Optimal no. of clusters: 10
[2025-10-06T18:24:26.590+0000] {taskinstance.py:1768} ERROR - Task failed with exception
Traceback (most recent call last):
  File "/home/airflow/.local/lib/python3.7/site-packages/airflow/operators/python.py", line 175, in execute
    return_value = self.execute_callable()
  File "/home/airflow/.local/lib/python3.7/site-packages/airflow/operators/python.py", line 192, in execute_callable
    return self.python_callable(*self.op_args, **self.op_kwargs)
  File "/opt/airflow/dags/src/lab.py", line 125, in load_model_elbow
    pred = loaded_model.predict(df)[0]
AttributeError: 'dict' object has no attribute 'predict'
[2025-10-06T18:24:26.592+0000] {taskinstance.py:1323} INFO - Marking task as FAILED. dag_id=Airflow_Lab1, task_id=load_model_task, execution_date=20251006T182418, start_date=20251006T182426, end_date=20251006T182426
[2025-10-06T18:24:26.596+0000] {standard_task_runner.py:105} ERROR - Failed to execute job 28 for task load_model_task ('dict' object has no attribute 'predict'; 8553)
[2025-10-06T18:24:26.636+0000] {local_task_job.py:208} INFO - Task exited with return code 1
[2025-10-06T18:24:26.645+0000] {taskinstance.py:2578} INFO - 0 downstream tasks scheduled from follow-on schedule check
